distributed.nanny - INFO -         Start Nanny at: 'tcp://10.12.205.21:46325'
distributed.worker - INFO -       Start worker at:   tcp://10.12.205.21:33392
distributed.worker - INFO -          Listening to:   tcp://10.12.205.21:33392
distributed.worker - INFO -          dashboard at:         10.12.205.21:45786
distributed.worker - INFO - Waiting to connect to:   tcp://10.12.205.30:44294
distributed.worker - INFO - -------------------------------------------------
distributed.worker - INFO -               Threads:                          4
distributed.worker - INFO -                Memory:                   40.00 GB
distributed.worker - INFO -       Local Directory: /glade/u/home/apinard/ldcpy/docs/source/notebooks/dask-worker-space/worker-0v7y3wk9
distributed.worker - INFO - -------------------------------------------------
distributed.worker - INFO -         Registered to:   tcp://10.12.205.30:44294
distributed.worker - INFO - -------------------------------------------------
distributed.core - INFO - Starting established connection
distributed.worker - ERROR - failed during get data with tcp://10.12.205.21:33392 -> tcp://10.12.205.21:42558
Traceback (most recent call last):
  File "/ncar/usr/jupyterhub/envs/cmip6-201910/lib/python3.7/site-packages/distributed/comm/tcp.py", line 188, in read
    n_frames = await stream.read_bytes(8)
tornado.iostream.StreamClosedError: Stream is closed

During handling of the above exception, another exception occurred:

Traceback (most recent call last):
  File "/ncar/usr/jupyterhub/envs/cmip6-201910/lib/python3.7/site-packages/distributed/worker.py", line 1249, in get_data
    response = await comm.read(deserializers=serializers)
  File "/ncar/usr/jupyterhub/envs/cmip6-201910/lib/python3.7/site-packages/distributed/comm/tcp.py", line 208, in read
    convert_stream_closed_error(self, e)
  File "/ncar/usr/jupyterhub/envs/cmip6-201910/lib/python3.7/site-packages/distributed/comm/tcp.py", line 123, in convert_stream_closed_error
    raise CommClosedError("in %s: %s" % (obj, exc))
distributed.comm.core.CommClosedError: in <closed TCP>: Stream is closed
distributed.core - INFO - Lost connection to 'tcp://10.12.205.21:37722': in <closed TCP>: Stream is closed
distributed.worker - ERROR - failed during get data with tcp://10.12.205.21:33392 -> tcp://10.12.205.14:36436
Traceback (most recent call last):
  File "/ncar/usr/jupyterhub/envs/cmip6-201910/lib/python3.7/site-packages/distributed/comm/tcp.py", line 251, in write
    await future
tornado.iostream.StreamClosedError: Stream is closed

During handling of the above exception, another exception occurred:

Traceback (most recent call last):
  File "/ncar/usr/jupyterhub/envs/cmip6-201910/lib/python3.7/site-packages/distributed/worker.py", line 1248, in get_data
    compressed = await comm.write(msg, serializers=serializers)
  File "/ncar/usr/jupyterhub/envs/cmip6-201910/lib/python3.7/site-packages/distributed/comm/tcp.py", line 255, in write
    convert_stream_closed_error(self, e)
  File "/ncar/usr/jupyterhub/envs/cmip6-201910/lib/python3.7/site-packages/distributed/comm/tcp.py", line 121, in convert_stream_closed_error
    raise CommClosedError("in %s: %s: %s" % (obj, exc.__class__.__name__, exc))
distributed.comm.core.CommClosedError: in <closed TCP>: BrokenPipeError: [Errno 32] Broken pipe
distributed.core - INFO - Lost connection to 'tcp://10.12.205.14:46680': in <closed TCP>: BrokenPipeError: [Errno 32] Broken pipe
slurmstepd: error: *** JOB 5760546 ON casper12 CANCELLED AT 2020-08-27T22:47:07 DUE TO TIME LIMIT ***
