distributed.nanny - INFO -         Start Nanny at: 'tcp://10.12.205.20:33882'
distributed.diskutils - INFO - Found stale lock file and directory '/glade/u/home/apinard/ldcpy/docs/source/notebooks/dask-worker-space/worker-x1q5v_xk', purging
distributed.worker - INFO -       Start worker at:   tcp://10.12.205.20:46725
distributed.worker - INFO -          Listening to:   tcp://10.12.205.20:46725
distributed.worker - INFO -          dashboard at:         10.12.205.20:40278
distributed.worker - INFO - Waiting to connect to:   tcp://10.12.205.19:46050
distributed.worker - INFO - -------------------------------------------------
distributed.worker - INFO -               Threads:                          4
distributed.worker - INFO -                Memory:                   40.00 GB
distributed.worker - INFO -       Local Directory: /glade/u/home/apinard/ldcpy/docs/source/notebooks/dask-worker-space/worker-nqd89saf
distributed.worker - INFO - -------------------------------------------------
distributed.worker - INFO -         Registered to:   tcp://10.12.205.19:46050
distributed.worker - INFO - -------------------------------------------------
distributed.core - INFO - Starting established connection
distributed.worker - WARNING -  Compute Failed
Function:  preprocess_vars
args:      (<xarray.Dataset>
Dimensions:       (ilev: 31, lat: 192, lev: 30, lon: 288, nbnd: 2, slat: 191, slon: 288, time: 31390)
Coordinates:
  * ilev          (ilev) float64 2.255 5.032 10.16 18.56 ... 967.5 985.1 1e+03
  * lat           (lat) float64 -90.0 -89.06 -88.12 -87.17 ... 88.12 89.06 90.0
  * lev           (lev) float64 3.643 7.595 14.36 24.61 ... 957.5 976.3 992.6
  * lon           (lon) float64 0.0 1.25 2.5 3.75 ... 355.0 356.2 357.5 358.8
  * slat          (slat) float64 -89.53 -88.59 -87.64 ... 87.64 88.59 89.53
  * slon          (slon) float64 -0.625 0.625 1.875 3.125 ... 355.6 356.9 358.1
  * time          (time) object 1920-01-01 00:00:00 ... 2005-12-31 00:00:00
Dimensions without coordinates: nbnd
Data variables:
    P0            float64 ...
    PRECT         (time, lat, lon) float32 dask.array<chunksize=(500, 192, 288), meta=np.ndarray>
    ch4vmr        (time) float64 dask.array<chunksize=(500,), meta=np.ndarray>
    co2vmr        (time) float64 dask.array<chunksize=(500,)
kwargs:    {}
Exception: KeyError('TS')

distributed.worker - INFO - Failed to put key in memory
Traceback (most recent call last):
  File "/ncar/usr/jupyterhub/envs/cmip6-201910/lib/python3.7/site-packages/distributed/worker.py", line 1671, in transition_executing_done
    self.put_key_in_memory(key, value, transition=False)
  File "/ncar/usr/jupyterhub/envs/cmip6-201910/lib/python3.7/site-packages/distributed/worker.py", line 1894, in put_key_in_memory
    self.data[key] = value
  File "/ncar/usr/jupyterhub/envs/cmip6-201910/lib/python3.7/site-packages/zict/buffer.py", line 87, in __setitem__
    self.fast[key] = value
  File "/ncar/usr/jupyterhub/envs/cmip6-201910/lib/python3.7/site-packages/zict/lru.py", line 70, in __setitem__
    self.evict()
  File "/ncar/usr/jupyterhub/envs/cmip6-201910/lib/python3.7/site-packages/zict/lru.py", line 89, in evict
    cb(k, v)
  File "/ncar/usr/jupyterhub/envs/cmip6-201910/lib/python3.7/site-packages/zict/buffer.py", line 60, in fast_to_slow
    self.slow[key] = value
  File "/ncar/usr/jupyterhub/envs/cmip6-201910/lib/python3.7/site-packages/zict/func.py", line 41, in __setitem__
    self.d[key] = self.dump(value)
  File "/ncar/usr/jupyterhub/envs/cmip6-201910/lib/python3.7/site-packages/zict/file.py", line 79, in __setitem__
    with open(os.path.join(self.directory, _safe_key(key)), "wb") as f:
FileNotFoundError: [Errno 2] No such file or directory: '/glade/u/home/apinard/ldcpy/docs/source/notebooks/dask-worker-space/worker-nqd89saf/storage/%28%27concatenate-cd2a3a1bb358cd7d0785eb74aaecec34%27%2C%200%2C%200%2C%200%2C%200%29'
distributed.worker - INFO - Failed to put key in memory
Traceback (most recent call last):
  File "/ncar/usr/jupyterhub/envs/cmip6-201910/lib/python3.7/site-packages/distributed/worker.py", line 1671, in transition_executing_done
    self.put_key_in_memory(key, value, transition=False)
  File "/ncar/usr/jupyterhub/envs/cmip6-201910/lib/python3.7/site-packages/distributed/worker.py", line 1894, in put_key_in_memory
    self.data[key] = value
  File "/ncar/usr/jupyterhub/envs/cmip6-201910/lib/python3.7/site-packages/zict/buffer.py", line 87, in __setitem__
    self.fast[key] = value
  File "/ncar/usr/jupyterhub/envs/cmip6-201910/lib/python3.7/site-packages/zict/lru.py", line 70, in __setitem__
    self.evict()
  File "/ncar/usr/jupyterhub/envs/cmip6-201910/lib/python3.7/site-packages/zict/lru.py", line 89, in evict
    cb(k, v)
  File "/ncar/usr/jupyterhub/envs/cmip6-201910/lib/python3.7/site-packages/zict/buffer.py", line 60, in fast_to_slow
    self.slow[key] = value
  File "/ncar/usr/jupyterhub/envs/cmip6-201910/lib/python3.7/site-packages/zict/func.py", line 41, in __setitem__
    self.d[key] = self.dump(value)
  File "/ncar/usr/jupyterhub/envs/cmip6-201910/lib/python3.7/site-packages/zict/file.py", line 79, in __setitem__
    with open(os.path.join(self.directory, _safe_key(key)), "wb") as f:
FileNotFoundError: [Errno 2] No such file or directory: '/glade/u/home/apinard/ldcpy/docs/source/notebooks/dask-worker-space/worker-nqd89saf/storage/%28%27concatenate-cd2a3a1bb358cd7d0785eb74aaecec34%27%2C%201%2C%200%2C%200%2C%200%29'
distributed.worker - INFO - Failed to put key in memory
Traceback (most recent call last):
  File "/ncar/usr/jupyterhub/envs/cmip6-201910/lib/python3.7/site-packages/distributed/worker.py", line 1671, in transition_executing_done
    self.put_key_in_memory(key, value, transition=False)
  File "/ncar/usr/jupyterhub/envs/cmip6-201910/lib/python3.7/site-packages/distributed/worker.py", line 1894, in put_key_in_memory
    self.data[key] = value
  File "/ncar/usr/jupyterhub/envs/cmip6-201910/lib/python3.7/site-packages/zict/buffer.py", line 87, in __setitem__
    self.fast[key] = value
  File "/ncar/usr/jupyterhub/envs/cmip6-201910/lib/python3.7/site-packages/zict/lru.py", line 70, in __setitem__
    self.evict()
  File "/ncar/usr/jupyterhub/envs/cmip6-201910/lib/python3.7/site-packages/zict/lru.py", line 89, in evict
    cb(k, v)
  File "/ncar/usr/jupyterhub/envs/cmip6-201910/lib/python3.7/site-packages/zict/buffer.py", line 60, in fast_to_slow
    self.slow[key] = value
  File "/ncar/usr/jupyterhub/envs/cmip6-201910/lib/python3.7/site-packages/zict/func.py", line 41, in __setitem__
    self.d[key] = self.dump(value)
  File "/ncar/usr/jupyterhub/envs/cmip6-201910/lib/python3.7/site-packages/zict/file.py", line 79, in __setitem__
    with open(os.path.join(self.directory, _safe_key(key)), "wb") as f:
FileNotFoundError: [Errno 2] No such file or directory: '/glade/u/home/apinard/ldcpy/docs/source/notebooks/dask-worker-space/worker-nqd89saf/storage/%28%27concatenate-cd2a3a1bb358cd7d0785eb74aaecec34%27%2C%200%2C%201%2C%200%2C%200%29'
distributed.worker - INFO - Failed to put key in memory
Traceback (most recent call last):
  File "/ncar/usr/jupyterhub/envs/cmip6-201910/lib/python3.7/site-packages/distributed/worker.py", line 1671, in transition_executing_done
    self.put_key_in_memory(key, value, transition=False)
  File "/ncar/usr/jupyterhub/envs/cmip6-201910/lib/python3.7/site-packages/distributed/worker.py", line 1894, in put_key_in_memory
    self.data[key] = value
  File "/ncar/usr/jupyterhub/envs/cmip6-201910/lib/python3.7/site-packages/zict/buffer.py", line 87, in __setitem__
    self.fast[key] = value
  File "/ncar/usr/jupyterhub/envs/cmip6-201910/lib/python3.7/site-packages/zict/lru.py", line 70, in __setitem__
    self.evict()
  File "/ncar/usr/jupyterhub/envs/cmip6-201910/lib/python3.7/site-packages/zict/lru.py", line 89, in evict
    cb(k, v)
  File "/ncar/usr/jupyterhub/envs/cmip6-201910/lib/python3.7/site-packages/zict/buffer.py", line 60, in fast_to_slow
    self.slow[key] = value
  File "/ncar/usr/jupyterhub/envs/cmip6-201910/lib/python3.7/site-packages/zict/func.py", line 41, in __setitem__
    self.d[key] = self.dump(value)
  File "/ncar/usr/jupyterhub/envs/cmip6-201910/lib/python3.7/site-packages/zict/file.py", line 79, in __setitem__
    with open(os.path.join(self.directory, _safe_key(key)), "wb") as f:
FileNotFoundError: [Errno 2] No such file or directory: '/glade/u/home/apinard/ldcpy/docs/source/notebooks/dask-worker-space/worker-nqd89saf/storage/%28%27concatenate-cd2a3a1bb358cd7d0785eb74aaecec34%27%2C%201%2C%201%2C%200%2C%200%29'
distributed.worker - INFO - Failed to put key in memory
Traceback (most recent call last):
  File "/ncar/usr/jupyterhub/envs/cmip6-201910/lib/python3.7/site-packages/distributed/worker.py", line 1671, in transition_executing_done
    self.put_key_in_memory(key, value, transition=False)
  File "/ncar/usr/jupyterhub/envs/cmip6-201910/lib/python3.7/site-packages/distributed/worker.py", line 1894, in put_key_in_memory
    self.data[key] = value
  File "/ncar/usr/jupyterhub/envs/cmip6-201910/lib/python3.7/site-packages/zict/buffer.py", line 87, in __setitem__
    self.fast[key] = value
  File "/ncar/usr/jupyterhub/envs/cmip6-201910/lib/python3.7/site-packages/zict/lru.py", line 70, in __setitem__
    self.evict()
  File "/ncar/usr/jupyterhub/envs/cmip6-201910/lib/python3.7/site-packages/zict/lru.py", line 89, in evict
    cb(k, v)
  File "/ncar/usr/jupyterhub/envs/cmip6-201910/lib/python3.7/site-packages/zict/buffer.py", line 60, in fast_to_slow
    self.slow[key] = value
  File "/ncar/usr/jupyterhub/envs/cmip6-201910/lib/python3.7/site-packages/zict/func.py", line 41, in __setitem__
    self.d[key] = self.dump(value)
  File "/ncar/usr/jupyterhub/envs/cmip6-201910/lib/python3.7/site-packages/zict/file.py", line 79, in __setitem__
    with open(os.path.join(self.directory, _safe_key(key)), "wb") as f:
FileNotFoundError: [Errno 2] No such file or directory: '/glade/u/home/apinard/ldcpy/docs/source/notebooks/dask-worker-space/worker-nqd89saf/storage/%28%27concatenate-cd2a3a1bb358cd7d0785eb74aaecec34%27%2C%200%2C%202%2C%200%2C%200%29'
distributed.worker - INFO - Failed to put key in memory
Traceback (most recent call last):
  File "/ncar/usr/jupyterhub/envs/cmip6-201910/lib/python3.7/site-packages/distributed/worker.py", line 1671, in transition_executing_done
    self.put_key_in_memory(key, value, transition=False)
  File "/ncar/usr/jupyterhub/envs/cmip6-201910/lib/python3.7/site-packages/distributed/worker.py", line 1894, in put_key_in_memory
    self.data[key] = value
  File "/ncar/usr/jupyterhub/envs/cmip6-201910/lib/python3.7/site-packages/zict/buffer.py", line 87, in __setitem__
    self.fast[key] = value
  File "/ncar/usr/jupyterhub/envs/cmip6-201910/lib/python3.7/site-packages/zict/lru.py", line 70, in __setitem__
    self.evict()
  File "/ncar/usr/jupyterhub/envs/cmip6-201910/lib/python3.7/site-packages/zict/lru.py", line 89, in evict
    cb(k, v)
  File "/ncar/usr/jupyterhub/envs/cmip6-201910/lib/python3.7/site-packages/zict/buffer.py", line 60, in fast_to_slow
    self.slow[key] = value
  File "/ncar/usr/jupyterhub/envs/cmip6-201910/lib/python3.7/site-packages/zict/func.py", line 41, in __setitem__
    self.d[key] = self.dump(value)
  File "/ncar/usr/jupyterhub/envs/cmip6-201910/lib/python3.7/site-packages/zict/file.py", line 79, in __setitem__
    with open(os.path.join(self.directory, _safe_key(key)), "wb") as f:
FileNotFoundError: [Errno 2] No such file or directory: '/glade/u/home/apinard/ldcpy/docs/source/notebooks/dask-worker-space/worker-nqd89saf/storage/%28%27concatenate-cd2a3a1bb358cd7d0785eb74aaecec34%27%2C%201%2C%202%2C%200%2C%200%29'
distributed.worker - INFO - Failed to put key in memory
Traceback (most recent call last):
  File "/ncar/usr/jupyterhub/envs/cmip6-201910/lib/python3.7/site-packages/distributed/worker.py", line 1671, in transition_executing_done
    self.put_key_in_memory(key, value, transition=False)
  File "/ncar/usr/jupyterhub/envs/cmip6-201910/lib/python3.7/site-packages/distributed/worker.py", line 1894, in put_key_in_memory
    self.data[key] = value
  File "/ncar/usr/jupyterhub/envs/cmip6-201910/lib/python3.7/site-packages/zict/buffer.py", line 87, in __setitem__
    self.fast[key] = value
  File "/ncar/usr/jupyterhub/envs/cmip6-201910/lib/python3.7/site-packages/zict/lru.py", line 70, in __setitem__
    self.evict()
  File "/ncar/usr/jupyterhub/envs/cmip6-201910/lib/python3.7/site-packages/zict/lru.py", line 89, in evict
    cb(k, v)
  File "/ncar/usr/jupyterhub/envs/cmip6-201910/lib/python3.7/site-packages/zict/buffer.py", line 60, in fast_to_slow
    self.slow[key] = value
  File "/ncar/usr/jupyterhub/envs/cmip6-201910/lib/python3.7/site-packages/zict/func.py", line 41, in __setitem__
    self.d[key] = self.dump(value)
  File "/ncar/usr/jupyterhub/envs/cmip6-201910/lib/python3.7/site-packages/zict/file.py", line 79, in __setitem__
    with open(os.path.join(self.directory, _safe_key(key)), "wb") as f:
FileNotFoundError: [Errno 2] No such file or directory: '/glade/u/home/apinard/ldcpy/docs/source/notebooks/dask-worker-space/worker-nqd89saf/storage/%28%27concatenate-273084c8a8aa9ad424d6035910054d34%27%2C%200%2C%2038%2C%200%2C%200%29'
distributed.worker - INFO - Failed to put key in memory
Traceback (most recent call last):
  File "/ncar/usr/jupyterhub/envs/cmip6-201910/lib/python3.7/site-packages/distributed/worker.py", line 1671, in transition_executing_done
    self.put_key_in_memory(key, value, transition=False)
  File "/ncar/usr/jupyterhub/envs/cmip6-201910/lib/python3.7/site-packages/distributed/worker.py", line 1894, in put_key_in_memory
    self.data[key] = value
  File "/ncar/usr/jupyterhub/envs/cmip6-201910/lib/python3.7/site-packages/zict/buffer.py", line 87, in __setitem__
    self.fast[key] = value
  File "/ncar/usr/jupyterhub/envs/cmip6-201910/lib/python3.7/site-packages/zict/lru.py", line 70, in __setitem__
    self.evict()
  File "/ncar/usr/jupyterhub/envs/cmip6-201910/lib/python3.7/site-packages/zict/lru.py", line 89, in evict
    cb(k, v)
  File "/ncar/usr/jupyterhub/envs/cmip6-201910/lib/python3.7/site-packages/zict/buffer.py", line 60, in fast_to_slow
    self.slow[key] = value
  File "/ncar/usr/jupyterhub/envs/cmip6-201910/lib/python3.7/site-packages/zict/func.py", line 41, in __setitem__
    self.d[key] = self.dump(value)
  File "/ncar/usr/jupyterhub/envs/cmip6-201910/lib/python3.7/site-packages/zict/file.py", line 79, in __setitem__
    with open(os.path.join(self.directory, _safe_key(key)), "wb") as f:
FileNotFoundError: [Errno 2] No such file or directory: '/glade/u/home/apinard/ldcpy/docs/source/notebooks/dask-worker-space/worker-nqd89saf/storage/%28%27concatenate-273084c8a8aa9ad424d6035910054d34%27%2C%201%2C%2038%2C%200%2C%200%29'
distributed.utils_perf - INFO - full garbage collection released 350.53 MB from 255 reference cycles (threshold: 10.00 MB)
distributed.worker - ERROR - "('concatenate-273084c8a8aa9ad424d6035910054d34', 1, 38, 0, 0)"
Traceback (most recent call last):
  File "/ncar/usr/jupyterhub/envs/cmip6-201910/lib/python3.7/site-packages/distributed/worker.py", line 2483, in execute
    data[k] = self.data[k]
  File "/ncar/usr/jupyterhub/envs/cmip6-201910/lib/python3.7/site-packages/zict/buffer.py", line 80, in __getitem__
    raise KeyError(key)
KeyError: "('concatenate-273084c8a8aa9ad424d6035910054d34', 1, 38, 0, 0)"

During handling of the above exception, another exception occurred:

Traceback (most recent call last):
  File "/ncar/usr/jupyterhub/envs/cmip6-201910/lib/python3.7/site-packages/distributed/worker.py", line 2487, in execute
    data[k] = Actor(type(self.actors[k]), self.address, k, self)
KeyError: "('concatenate-273084c8a8aa9ad424d6035910054d34', 1, 38, 0, 0)"
distributed.worker - ERROR - "('concatenate-273084c8a8aa9ad424d6035910054d34', 0, 38, 0, 0)"
Traceback (most recent call last):
  File "/ncar/usr/jupyterhub/envs/cmip6-201910/lib/python3.7/site-packages/distributed/worker.py", line 2483, in execute
    data[k] = self.data[k]
  File "/ncar/usr/jupyterhub/envs/cmip6-201910/lib/python3.7/site-packages/zict/buffer.py", line 80, in __getitem__
    raise KeyError(key)
KeyError: "('concatenate-273084c8a8aa9ad424d6035910054d34', 0, 38, 0, 0)"

During handling of the above exception, another exception occurred:

Traceback (most recent call last):
  File "/ncar/usr/jupyterhub/envs/cmip6-201910/lib/python3.7/site-packages/distributed/worker.py", line 2487, in execute
    data[k] = Actor(type(self.actors[k]), self.address, k, self)
KeyError: "('concatenate-273084c8a8aa9ad424d6035910054d34', 0, 38, 0, 0)"
tornado.application - ERROR - Exception in callback functools.partial(<bound method IOLoop._discard_future_result of <tornado.platform.asyncio.AsyncIOLoop object at 0x2baa512fc710>>, <Task finished coro=<Worker.execute() done, defined at /ncar/usr/jupyterhub/envs/cmip6-201910/lib/python3.7/site-packages/distributed/worker.py:2466> exception=KeyError("('concatenate-273084c8a8aa9ad424d6035910054d34', 1, 38, 0, 0)")>)
Traceback (most recent call last):
  File "/ncar/usr/jupyterhub/envs/cmip6-201910/lib/python3.7/site-packages/distributed/worker.py", line 2483, in execute
    data[k] = self.data[k]
  File "/ncar/usr/jupyterhub/envs/cmip6-201910/lib/python3.7/site-packages/zict/buffer.py", line 80, in __getitem__
    raise KeyError(key)
KeyError: "('concatenate-273084c8a8aa9ad424d6035910054d34', 1, 38, 0, 0)"

During handling of the above exception, another exception occurred:

Traceback (most recent call last):
  File "/ncar/usr/jupyterhub/envs/cmip6-201910/lib/python3.7/site-packages/tornado/ioloop.py", line 743, in _run_callback
    ret = callback()
  File "/ncar/usr/jupyterhub/envs/cmip6-201910/lib/python3.7/site-packages/tornado/ioloop.py", line 767, in _discard_future_result
    future.result()
  File "/ncar/usr/jupyterhub/envs/cmip6-201910/lib/python3.7/site-packages/distributed/worker.py", line 2487, in execute
    data[k] = Actor(type(self.actors[k]), self.address, k, self)
KeyError: "('concatenate-273084c8a8aa9ad424d6035910054d34', 1, 38, 0, 0)"
tornado.application - ERROR - Exception in callback functools.partial(<bound method IOLoop._discard_future_result of <tornado.platform.asyncio.AsyncIOLoop object at 0x2baa512fc710>>, <Task finished coro=<Worker.execute() done, defined at /ncar/usr/jupyterhub/envs/cmip6-201910/lib/python3.7/site-packages/distributed/worker.py:2466> exception=KeyError("('concatenate-273084c8a8aa9ad424d6035910054d34', 0, 38, 0, 0)")>)
Traceback (most recent call last):
  File "/ncar/usr/jupyterhub/envs/cmip6-201910/lib/python3.7/site-packages/distributed/worker.py", line 2483, in execute
    data[k] = self.data[k]
  File "/ncar/usr/jupyterhub/envs/cmip6-201910/lib/python3.7/site-packages/zict/buffer.py", line 80, in __getitem__
    raise KeyError(key)
KeyError: "('concatenate-273084c8a8aa9ad424d6035910054d34', 0, 38, 0, 0)"

During handling of the above exception, another exception occurred:

Traceback (most recent call last):
  File "/ncar/usr/jupyterhub/envs/cmip6-201910/lib/python3.7/site-packages/tornado/ioloop.py", line 743, in _run_callback
    ret = callback()
  File "/ncar/usr/jupyterhub/envs/cmip6-201910/lib/python3.7/site-packages/tornado/ioloop.py", line 767, in _discard_future_result
    future.result()
  File "/ncar/usr/jupyterhub/envs/cmip6-201910/lib/python3.7/site-packages/distributed/worker.py", line 2487, in execute
    data[k] = Actor(type(self.actors[k]), self.address, k, self)
KeyError: "('concatenate-273084c8a8aa9ad424d6035910054d34', 0, 38, 0, 0)"
slurmstepd: error: *** JOB 5926486 ON casper11 CANCELLED AT 2020-09-23T15:55:40 DUE TO TIME LIMIT ***
